Ocorreu um erro inesperado:
Traceback (most recent call last):
  File "c:\Users\rodiney.nascimento\OneDrive - PEREZ DE REZENDE ADVOCACIA\Documentos\Python Scripts\rename\app\main.py", line 21, in <module>
    main()
  File "c:\Users\rodiney.nascimento\OneDrive - PEREZ DE REZENDE ADVOCACIA\Documentos\Python Scripts\rename\app\main.py", line 14, in main
    window = GerenciadorPdf()
             ^^^^^^^^^^^^^^^^
  File "c:\Users\rodiney.nascimento\OneDrive - PEREZ DE REZENDE ADVOCACIA\Documentos\Python Scripts\rename\app\utils\gerenciador_pdf.py", line 13, in __init__
    self.init_ui()
  File "c:\Users\rodiney.nascimento\OneDrive - PEREZ DE REZENDE ADVOCACIA\Documentos\Python Scripts\rename\app\utils\gerenciador_pdf.py", line 17, in init_ui
    self.setup_widgets()
  File "c:\Users\rodiney.nascimento\OneDrive - PEREZ DE REZENDE ADVOCACIA\Documentos\Python Scripts\rename\app\utils\gerenciador_pdf.py", line 36, in setup_widgets
    self.remove_page_button.clicked.connect(self.remove_page)
                                            ^^^^^^^^^^^^^^^^
AttributeError: 'GerenciadorPdf' object has no attribute 'remove_page'
