Ocorreu um erro inesperado:
Traceback (most recent call last):
  File "C:\Users\rodiney.nascimento\OneDrive - PEREZ DE REZENDE ADVOCACIA\Documentos\Python Scripts\rename\app\main.py", line 21, in <module>
    main()
  File "C:\Users\rodiney.nascimento\OneDrive - PEREZ DE REZENDE ADVOCACIA\Documentos\Python Scripts\rename\app\main.py", line 14, in main
    window = GerenciadorPdf()
             ^^^^^^^^^^^^^^^^
  File "C:\Users\rodiney.nascimento\OneDrive - PEREZ DE REZENDE ADVOCACIA\Documentos\Python Scripts\rename\app\utils\gerenciador_pdf.py", line 14, in __init__
    self.init_ui()
  File "C:\Users\rodiney.nascimento\OneDrive - PEREZ DE REZENDE ADVOCACIA\Documentos\Python Scripts\rename\app\utils\gerenciador_pdf.py", line 18, in init_ui
    self.setup_widgets()
  File "C:\Users\rodiney.nascimento\OneDrive - PEREZ DE REZENDE ADVOCACIA\Documentos\Python Scripts\rename\app\utils\gerenciador_pdf.py", line 58, in setup_widgets
    self.layout.addWidget(self.checkbox_reduzir_imagem)
                          ^^^^^^^^^^^^^^^^^^^^^^^^^^^^
AttributeError: 'GerenciadorPdf' object has no attribute 'checkbox_reduzir_imagem'. Did you mean: 'chckbox_reduzir_imagem'?
